<sdf version='1.6'>
  <world name='default'>
    <light name='sun' type='directional'>
      <cast_shadows>1</cast_shadows>
      <pose frame=''>0 0 10 0 -0 0</pose>
      <diffuse>0.8 0.8 0.8 1</diffuse>
      <specular>0.1 0.1 0.1 1</specular>
      <attenuation>
        <range>1000</range>
        <constant>0.9</constant>
        <linear>0.01</linear>
        <quadratic>0.001</quadratic>
      </attenuation>
      <direction>-0.5 0.5 -1</direction>
    </light>
    <model name='ground_plane'>
      <static>1</static>
      <link name='link'>
        <collision name='collision'>
          <geometry>
            <plane>
              <normal>0 0 1</normal>
              <size>100 100</size>
            </plane>
          </geometry>
          <surface>
            <friction>
              <ode>
                <mu>100</mu>
                <mu2>50</mu2>
              </ode>
              <torsional>
                <ode/>
              </torsional>
            </friction>
            <contact>
              <ode/>
            </contact>
            <bounce/>
          </surface>
          <max_contacts>10</max_contacts>
        </collision>
        <visual name='visual'>
          <cast_shadows>0</cast_shadows>
          <geometry>
            <plane>
              <normal>0 0 1</normal>
              <size>100 100</size>
            </plane>
          </geometry>
          <material>
            <script>
              <uri>file://media/materials/scripts/gazebo.material</uri>
              <name>Gazebo/Grey</name>
            </script>
          </material>
        </visual>
        <self_collide>0</self_collide>
        <kinematic>0</kinematic>
      </link>
    </model>
    <gravity>0 0 -9.8</gravity>
    <magnetic_field>6e-06 2.3e-05 -4.2e-05</magnetic_field>
    <atmosphere type='adiabatic'/>
    <physics name='default_physics' default='0' type='ode'>
      <max_step_size>0.001</max_step_size>
      <real_time_factor>1</real_time_factor>
      <real_time_update_rate>1000</real_time_update_rate>
    </physics>
    <scene>
      <ambient>0.4 0.4 0.4 1</ambient>
      <background>0.7 0.7 0.7 1</background>
      <shadows>1</shadows>
    </scene>
    <spherical_coordinates>
      <surface_model>EARTH_WGS84</surface_model>
      <latitude_deg>0</latitude_deg>
      <longitude_deg>0</longitude_deg>
      <elevation>0</elevation>
      <heading_deg>0</heading_deg>
    </spherical_coordinates>
    <model name='Crevice_crossing'>
      <pose frame=''>1.74481 -0.037568 0 0 -0 0</pose>
      <link name='Stairs_1'>
        <visual name='Stairs_1_Visual_0'>
          <pose frame=''>-1.05017 -0.009236 0.1 0 -0 0</pose>
          <geometry>
            <box>
              <size>2 3.37 0.2</size>
            </box>
          </geometry>
          <material>
            <script>
              <uri>file://media/materials/scripts/gazebo.material</uri>
              <name>Gazebo/Wood</name>
            </script>
            <ambient>1 1 1 1</ambient>
          </material>
          <meta>
            <layer>0</layer>
          </meta>
        </visual>
        <collision name='Stairs_1_Collision_0'>
          <geometry>
            <box>
              <size>2 3.37 0.2</size>
            </box>
          </geometry>
          <pose frame=''>-1.05017 -0.009236 0.1 0 -0 0</pose>
          <max_contacts>10</max_contacts>
          <surface>
            <contact>
              <ode/>
            </contact>
            <bounce/>
            <friction>
              <torsional>
                <ode/>
              </torsional>
              <ode/>
            </friction>
          </surface>
        </collision>
        <self_collide>0</self_collide>
        <kinematic>0</kinematic>
      </link>
      <link name='Stairs_3'>
        <visual name='Stairs_3_Visual_0'>
          <pose frame=''>1.05017 0.001236 0.1 0 -0 0</pose>
          <geometry>
            <box>
              <size>2 3.386 0.2</size>
            </box>
          </geometry>
          <material>
            <script>
              <uri>file://media/materials/scripts/gazebo.material</uri>
              <name>Gazebo/CeilingTiled</name>
            </script>
            <ambient>1 1 1 1</ambient>
          </material>
          <meta>
            <layer>0</layer>
          </meta>
        </visual>
        <collision name='Stairs_3_Collision_0'>
          <geometry>
            <box>
              <size>2 3.386 0.2</size>
            </box>
          </geometry>
          <pose frame=''>1.05017 0.001236 0.1 0 -0 0</pose>
          <max_contacts>10</max_contacts>
          <surface>
            <contact>
              <ode/>
            </contact>
            <bounce/>
            <friction>
              <torsional>
                <ode/>
              </torsional>
              <ode/>
            </friction>
          </surface>
        </collision>
        <self_collide>0</self_collide>
        <kinematic>0</kinematic>
      </link>
      <static>1</static>
    </model>
    <state world_name='default'>
      <sim_time>127 954000000</sim_time>
      <real_time>46 846849314</real_time>
      <wall_time>1489847244 160019742</wall_time>
      <iterations>40718</iterations>
      <model name='Crevice_crossing'>
        <pose frame=''>1.74481 -0.037568 0 0 -0 0</pose>
        <scale>1 1 1</scale>
        <link name='Stairs_1'>
          <pose frame=''>1.74481 -0.037568 0 0 -0 0</pose>
          <velocity>0 0 0 0 -0 0</velocity>
          <acceleration>0 0 0 0 -0 0</acceleration>
          <wrench>0 0 0 0 -0 0</wrench>
        </link>
        <link name='Stairs_3'>
          <pose frame=''>1.74481 -0.037568 0 0 -0 0</pose>
          <velocity>0 0 0 0 -0 0</velocity>
          <acceleration>0 0 0 0 -0 0</acceleration>
          <wrench>0 0 0 0 -0 0</wrench>
        </link>
      </model>
      <model name='ground_plane'>
        <pose frame=''>0 0 0 0 -0 0</pose>
        <scale>1 1 1</scale>
        <link name='link'>
          <pose frame=''>0 0 0 0 -0 0</pose>
          <velocity>0 0 0 0 -0 0</velocity>
          <acceleration>0 0 0 0 -0 0</acceleration>
          <wrench>0 0 0 0 -0 0</wrench>
        </link>
      </model>
      <model name='robbie'>
        <pose frame=''>0.156357 0.004347 0.201343 2.1e-05 0.049459 0.021835</pose>
        <scale>1 1 1</scale>
        <link name='arm_left_link'>
          <pose frame=''>0.30774 0.295718 0.446169 9e-06 0.442278 0.021803</pose>
          <velocity>0.002726 0.000451 0.002504 -0.004243 0.010934 -0.006036</velocity>
          <acceleration>-3.54307 1.20415 6.32277 -2.3426 0.293745 -1.45042</acceleration>
          <wrench>-0.885767 0.301036 1.58069 0 -0 0</wrench>
        </link>
        <link name='arm_right_link'>
          <pose frame=''>0.320301 -0.280145 0.446162 7.6e-05 0.442343 0.021918</pose>
          <velocity>0.002962 -0.000917 0.002641 0.007678 0.012124 0.009893</velocity>
          <acceleration>-3.34549 -0.221036 6.87538 3.12343 1.06432 0.707018</acceleration>
          <wrench>-0.836373 -0.055259 1.71884 0 -0 0</wrench>
        </link>
        <link name='lhm_link'>
          <pose frame=''>-0.255855 -0.004654 0.366146 0.000106 1.09771 0.021932</pose>
          <velocity>0.004664 -0.001113 0.00204 -0.002249 -0.004914 0.0004</velocity>
          <acceleration>2.97309 0.096725 4.28796 0.147008 1.04342 2.16243</acceleration>
          <wrench>6.68945 0.217631 9.64791 0 -0 0</wrench>
        </link>
        <link name='lhm_wheel_left_link'>
          <pose frame=''>-0.251223 -0.217104 0.36614 3.14154 0.124396 -3.11976</pose>
          <velocity>0.003336 -0.001143 0.00335 0.247471 1.10488 -0.000269</velocity>
          <acceleration>-0.340114 0.018035 6.90247 -0.679482 -0.152021 2.83213</acceleration>
          <wrench>-0.068023 0.003607 1.38049 0 -0 0</wrench>
        </link>
        <link name='lhm_wheel_right_link'>
          <pose frame=''>-0.260494 0.207795 0.366144 -2.7e-05 -0.276593 0.021807</pose>
          <velocity>0.004519 -0.001111 -0.000501 0.280433 -1.00219 -0.006135</velocity>
          <acceleration>3.29741 0.109354 -1.20057 2.29277 -0.771956 -2.97957</acceleration>
          <wrench>0.659483 0.021871 -0.240114 0 -0 0</wrench>
        </link>
        <link name='shank_footprint'>
          <pose frame=''>0.156357 0.004347 0.201343 2.1e-05 0.049459 0.021835</pose>
          <velocity>0.000835 -0.000277 0.007311 0.000837 0.006898 0.00107</velocity>
          <acceleration>-3.36307 -0.01964 13.7104 2.49814 0.586335 -3.10261</acceleration>
          <wrench>-23.5415 -0.137478 95.9725 0 -0 0</wrench>
        </link>
        <link name='shoulder_left_link'>
          <pose frame=''>0.422479 0.138178 0.681151 2.5e-05 0.442257 0.021829</pose>
          <velocity>0.005126 -0.000434 0.000912 0.002978 0.010577 0.000188</velocity>
          <acceleration>1.37154 0.747255 4.24471 -2.80241 -0.44369 -1.51906</acceleration>
          <wrench>0.342885 0.186814 1.06118 0 -0 0</wrench>
        </link>
        <link name='shoulder_right_link'>
          <pose frame=''>0.428068 -0.11776 0.681146 4.2e-05 0.442326 0.021874</pose>
          <velocity>0.004991 -0.000339 0.000987 -0.000363 0.011613 0.002647</velocity>
          <acceleration>1.06568 -0.178839 4.49189 1.17168 1.35275 1.50231</acceleration>
          <wrench>0.26642 -0.04471 1.12297 0 -0 0</wrench>
        </link>
        <link name='stab_link'>
          <pose frame=''>0.390554 0.009457 0.37206 3.14155 1.17237 -3.1198</pose>
          <velocity>0.002067 -0.000155 0.006607 -0.001269 -0.010398 -0.003044</velocity>
          <acceleration>-2.49985 -0.257621 15.0329 2.49285 0.7827 -1.1302</acceleration>
          <wrench>-2.49985 -0.257621 15.0329 0 -0 0</wrench>
        </link>
        <link name='stab_wheel'>
          <pose frame=''>0.620904 0.01449 0.275064 3.14146 1.47266 -3.11989</pose>
          <velocity>0.000891 -0.000107 0.00841 -0.003346 -0.039671 -0.003414</velocity>
          <acceleration>-6.01088 -0.398116 16.7776 0.419758 -0.285702 -0.469725</acceleration>
          <wrench>-4.50816 -0.298587 12.5832 0 -0 0</wrench>
        </link>
        <link name='thigh_link'>
          <pose frame=''>0.492763 0.011689 0.403612 5.7e-05 -1.17227 0.02178</pose>
          <velocity>0.002406 -9.6e-05 0.001252 0.000862 0.007209 0.001123</velocity>
          <acceleration>-0.3479 0.042178 5.26179 2.3308 0.618534 -3.08568</acceleration>
          <wrench>-0.6958 0.084355 10.5236 0 -0 0</wrench>
        </link>
        <link name='torso_link'>
          <pose frame=''>0.158293 0.004382 0.544474 4.8e-05 1.09773 0.021875</pose>
          <velocity>0.003887 -0.000584 0.00304 0.001026 -0.001249 0.001163</velocity>
          <acceleration>1.85701 0.108591 8.29541 3.10815 1.1624 -3.09737</acceleration>
          <wrench>29.7122 1.73745 132.727 0 -0 0</wrench>
        </link>
        <link name='wheel_left_link'>
          <pose frame=''>0.163862 -0.113021 0.301249 0.00025 1.27685 0.022055</pose>
          <velocity>0.001491 -0.000449 0.011662 0.004437 0.014733 4.2e-05</velocity>
          <acceleration>-5.10112 -0.371516 28.06 -0.861316 -1.0945 -1.05504</acceleration>
          <wrench>-1.27528 -0.092879 7.01499 0 -0 0</wrench>
        </link>
        <link name='wheel_right_link'>
          <pose frame=''>0.158733 0.121924 0.301248 0.000219 1.27672 0.022032</pose>
          <velocity>0.001369 -0.000348 0.011398 0.003479 0.013624 0.00056</velocity>
          <acceleration>-4.70366 -0.065538 26.2035 -2.91595 0.040877 2.82989</acceleration>
          <wrench>-1.17592 -0.016384 6.55087 0 -0 0</wrench>
        </link>
      </model>
      <light name='sun'>
        <pose frame=''>0 0 10 0 -0 0</pose>
      </light>
    </state>
    <gui fullscreen='0'>
      <camera name='user_camera'>
        <pose frame=''>1.27379 -6.83148 1.59355 0 0.099643 1.51619</pose>
        <view_controller>orbit</view_controller>
        <projection_type>perspective</projection_type>
      </camera>
    </gui>
    <model name='robbie'>
      <link name='shank_footprint'>
        <pose frame=''>0 0 0 0 -0 0</pose>
        <inertial>
          <pose frame=''>0.163037 0 0.15934 0 -0 0</pose>
          <mass>7</mass>
          <inertia>
            <ixx>0.0904763</ixx>
            <ixy>0</ixy>
            <ixz>-0.0195421</ixz>
            <iyy>0.0870543</iyy>
            <iyz>0</iyz>
            <izz>0.137055</izz>
          </inertia>
        </inertial>
        <collision name='shank_footprint_fixed_joint_lump__shank_link_collision'>
          <pose frame=''>0 0 0.1 0 1.22173 0</pose>
          <geometry>
            <mesh>
              <scale>1 1 1</scale>
              <uri>/home/moyin/dev/autonomous_controllers/src/gazebo_sim/robbie_description/meshes/shank_collision.stl</uri>
            </mesh>
          </geometry>
          <max_contacts>10</max_contacts>
          <surface>
            <contact>
              <ode/>
            </contact>
            <bounce/>
            <friction>
              <torsional>
                <ode/>
              </torsional>
              <ode/>
            </friction>
          </surface>
        </collision>
        <visual name='shank_footprint_fixed_joint_lump__shank_link_visual'>
          <pose frame=''>0 0 0.1 0 1.22173 0</pose>
          <geometry>
            <mesh>
              <scale>1 1 1</scale>
              <uri>/home/moyin/dev/autonomous_controllers/src/gazebo_sim/robbie_description/meshes/shank.stl</uri>
            </mesh>
          </geometry>
        </visual>
        <self_collide>0</self_collide>
        <kinematic>0</kinematic>
      </link>
      <link name='thigh_link'>
        <pose frame=''>0.326073 0 0.218681 0 -1.22173 0</pose>
        <inertial>
          <pose frame=''>0 0 0.1815 0 -0 0</pose>
          <mass>2</mass>
          <inertia>
            <ixx>0.0465375</ixx>
            <ixy>0</ixy>
            <ixz>0</ixz>
            <iyy>0.0293927</iyy>
            <iyz>0</iyz>
            <izz>0.0267782</izz>
          </inertia>
        </inertial>
        <collision name='thigh_link_collision'>
          <pose frame=''>0 0 0 0 -0 0</pose>
          <geometry>
            <mesh>
              <scale>1 1 1</scale>
              <uri>/home/moyin/dev/autonomous_controllers/src/gazebo_sim/robbie_description/meshes/thigh_collision.stl</uri>
            </mesh>
          </geometry>
          <surface>
            <contact>
              <ode/>
            </contact>
            <friction>
              <ode/>
              <torsional>
                <ode/>
              </torsional>
            </friction>
            <bounce/>
          </surface>
          <max_contacts>10</max_contacts>
        </collision>
        <visual name='thigh_link_visual'>
          <pose frame=''>0 0 0 0 -0 0</pose>
          <geometry>
            <mesh>
              <scale>1 1 1</scale>
              <uri>/home/moyin/dev/autonomous_controllers/src/gazebo_sim/robbie_description/meshes/thigh.stl</uri>
            </mesh>
          </geometry>
          <material>
            <script>
              <name>Gazebo/Black</name>
              <uri>file://media/materials/scripts/gazebo.material</uri>
            </script>
          </material>
        </visual>
        <gravity>1</gravity>
        <velocity_decay/>
        <self_collide>0</self_collide>
        <kinematic>0</kinematic>
      </link>
      <joint name='knee_joint' type='revolute'>
        <child>thigh_link</child>
        <parent>shank_footprint</parent>
        <axis>
          <xyz>0 1 0</xyz>
          <limit>
            <lower>0</lower>
            <upper>1</upper>
            <effort>300</effort>
            <velocity>0.1</velocity>
          </limit>
          <dynamics>
            <damping>1</damping>
            <friction>0</friction>
            <spring_reference>0</spring_reference>
            <spring_stiffness>0</spring_stiffness>
          </dynamics>
          <use_parent_model_frame>1</use_parent_model_frame>
        </axis>
      </joint>
      <link name='torso_link'>
        <pose frame=''>-0.015035 0 0.342834 0 0.34827 0</pose>
        <inertial>
          <pose frame=''>0 0 0.192 0 -0 0</pose>
          <mass>16</mass>
          <inertia>
            <ixx>0.36941</ixx>
            <ixy>0</ixy>
            <ixz>0</ixz>
            <iyy>0.240302</iyy>
            <iyz>0</iyz>
            <izz>0.264109</izz>
          </inertia>
        </inertial>
        <collision name='torso_link_collision'>
          <pose frame=''>-0.03 0 -0.042 0 -0 0</pose>
          <geometry>
            <mesh>
              <scale>1 1 1</scale>
              <uri>/home/moyin/dev/autonomous_controllers/src/gazebo_sim/robbie_description/meshes/torso.stl</uri>
            </mesh>
          </geometry>
          <surface>
            <contact>
              <ode/>
            </contact>
            <friction>
              <ode/>
              <torsional>
                <ode/>
              </torsional>
            </friction>
            <bounce/>
          </surface>
          <max_contacts>10</max_contacts>
        </collision>
        <collision name='torso_link_fixed_joint_lump__camera_link_collision_1'>
          <pose frame=''>0 0 0.42 0 -0 0</pose>
          <geometry>
            <box>
              <size>0.05 0.05 0.05</size>
            </box>
          </geometry>
          <surface>
            <contact>
              <ode/>
            </contact>
            <friction>
              <ode/>
              <torsional>
                <ode/>
              </torsional>
            </friction>
            <bounce/>
          </surface>
          <max_contacts>10</max_contacts>
        </collision>
        <visual name='torso_link_visual'>
          <pose frame=''>-0.03 0 -0.042 0 -0 0</pose>
          <geometry>
            <mesh>
              <scale>1 1 1</scale>
              <uri>/home/moyin/dev/autonomous_controllers/src/gazebo_sim/robbie_description/meshes/torso.stl</uri>
            </mesh>
          </geometry>
          <material>
            <script>
              <name>Gazebo/White</name>
              <uri>file://media/materials/scripts/gazebo.material</uri>
            </script>
          </material>
        </visual>
        <visual name='torso_link_fixed_joint_lump__camera_link_visual_1'>
          <pose frame=''>0 0 0.42 0 -0 0</pose>
          <geometry>
            <box>
              <size>0.05 0.05 0.05</size>
            </box>
          </geometry>
          <material>
            <script>
              <uri>__default__</uri>
              <name>__default__</name>
            </script>
          </material>
        </visual>
        <velocity_decay/>
        <gravity>1</gravity>
        <velocity_decay/>
        <sensor name='camera1' type='camera'>
          <update_rate>30</update_rate>
          <camera name='head'>
            <horizontal_fov>1.39626</horizontal_fov>
            <image>
              <width>800</width>
              <height>800</height>
              <format>R8G8B8</format>
            </image>
            <clip>
              <near>0.02</near>
              <far>300</far>
            </clip>
            <noise>
              <type>gaussian</type>
              <mean>0</mean>
              <stddev>0.007</stddev>
            </noise>
          </camera>
          <plugin name='camera_controller' filename='libgazebo_ros_camera.so'>
            <alwaysOn>true</alwaysOn>
            <updateRate>0.0</updateRate>
            <cameraName>robbie/camera1</cameraName>
            <imageTopicName>image_raw</imageTopicName>
            <cameraInfoTopicName>camera_info</cameraInfoTopicName>
            <frameName>camera_link</frameName>
            <hackBaseline>0.07</hackBaseline>
            <distortionK1>0.0</distortionK1>
            <distortionK2>0.0</distortionK2>
            <distortionK3>0.0</distortionK3>
            <distortionT1>0.0</distortionT1>
            <distortionT2>0.0</distortionT2>
            <robotNamespace>/</robotNamespace>
          </plugin>
          <pose frame=''>0 0 0.42 0 -0 0</pose>
        </sensor>
        <self_collide>0</self_collide>
        <kinematic>0</kinematic>
      </link>
      <joint name='hip_joint' type='revolute'>
        <child>torso_link</child>
        <parent>thigh_link</parent>
        <axis>
          <xyz>0 1 0</xyz>
          <limit>
            <lower>-1</lower>
            <upper>0.7</upper>
            <effort>300</effort>
            <velocity>0.1</velocity>
          </limit>
          <dynamics>
            <damping>1</damping>
            <friction>0</friction>
            <spring_reference>0</spring_reference>
            <spring_stiffness>0</spring_stiffness>
          </dynamics>
          <use_parent_model_frame>1</use_parent_model_frame>
        </axis>
      </joint>
      <link name='lhm_link'>
        <pose frame=''>-0.060298 0 0.306074 0 0.34827 0</pose>
        <inertial>
          <pose frame=''>0 0 0.02 0 -0 0</pose>
          <mass>2.25</mass>
          <inertia>
            <ixx>0.021468</ixx>
            <ixy>0</ixy>
            <ixz>0</ixz>
            <iyy>0.0213977</iyy>
            <iyz>0</iyz>
            <izz>0.000529687</izz>
          </inertia>
        </inertial>
        <collision name='lhm_link_collision'>
          <pose frame=''>0 0 0 0 -0 0</pose>
          <geometry>
            <mesh>
              <scale>1 1 1</scale>
              <uri>/home/moyin/dev/autonomous_controllers/src/gazebo_sim/robbie_description/meshes/butt_PART_collision.STL</uri>
            </mesh>
          </geometry>
          <max_contacts>10</max_contacts>
          <surface>
            <contact>
              <ode/>
            </contact>
            <bounce/>
            <friction>
              <torsional>
                <ode/>
              </torsional>
              <ode/>
            </friction>
          </surface>
        </collision>
        <visual name='lhm_link_visual'>
          <pose frame=''>0 0 0 0 -0 0</pose>
          <geometry>
            <mesh>
              <scale>1 1 1</scale>
              <uri>/home/moyin/dev/autonomous_controllers/src/gazebo_sim/robbie_description/meshes/butt_PART.STL</uri>
            </mesh>
          </geometry>
        </visual>
        <self_collide>0</self_collide>
        <kinematic>0</kinematic>
      </link>
      <joint name='lhm_torso_joint' type='prismatic'>
        <child>lhm_link</child>
        <parent>torso_link</parent>
        <axis>
          <xyz>0.341272 0 0.939965</xyz>
          <limit>
            <lower>-0.4</lower>
            <upper>0</upper>
            <effort>300</effort>
            <velocity>0.1</velocity>
          </limit>
          <dynamics>
            <damping>1</damping>
            <friction>0</friction>
            <spring_reference>0</spring_reference>
            <spring_stiffness>0</spring_stiffness>
          </dynamics>
          <use_parent_model_frame>1</use_parent_model_frame>
        </axis>
      </joint>
      <link name='lhm_wheel_left_link'>
        <pose frame=''>-0.060298 -0.2125 0.306074 0 0.34827 0</pose>
        <inertial>
          <pose frame=''>0 0 0 0 -0 0</pose>
          <mass>0.2</mass>
          <inertia>
            <ixx>0.000532739</ixx>
            <ixy>0</ixy>
            <ixz>0</ixz>
            <iyy>0.000532739</iyy>
            <iyz>0</iyz>
            <izz>0.00104397</izz>
          </inertia>
        </inertial>
        <collision name='lhm_wheel_left_link_collision'>
          <pose frame=''>0 0 0 0 -0 0</pose>
          <geometry>
            <mesh>
              <scale>1 1 1</scale>
              <uri>/home/moyin/dev/autonomous_controllers/src/gazebo_sim/robbie_description/meshes/butt_wheelFini_collision.STL</uri>
            </mesh>
          </geometry>
          <surface>
            <contact>
              <ode/>
            </contact>
            <friction>
              <ode/>
              <torsional>
                <ode/>
              </torsional>
            </friction>
            <bounce/>
          </surface>
          <max_contacts>10</max_contacts>
        </collision>
        <visual name='lhm_wheel_left_link_visual'>
          <pose frame=''>0 0 0 0 -0 0</pose>
          <geometry>
            <mesh>
              <scale>1 1 1</scale>
              <uri>/home/moyin/dev/autonomous_controllers/src/gazebo_sim/robbie_description/meshes/butt_wheelFini.STL</uri>
            </mesh>
          </geometry>
          <material>
            <script>
              <name>Gazebo/Black</name>
              <uri>file://media/materials/scripts/gazebo.material</uri>
            </script>
          </material>
        </visual>
        <gravity>1</gravity>
        <velocity_decay/>
        <self_collide>0</self_collide>
        <kinematic>0</kinematic>
      </link>
      <joint name='lhm_wheel_left_joint' type='revolute'>
        <child>lhm_wheel_left_link</child>
        <parent>lhm_link</parent>
        <axis>
          <xyz>0 1 0</xyz>
          <limit>
            <lower>-1e+16</lower>
            <upper>1e+16</upper>
          </limit>
          <dynamics>
            <spring_reference>0</spring_reference>
            <spring_stiffness>0</spring_stiffness>
          </dynamics>
          <use_parent_model_frame>1</use_parent_model_frame>
        </axis>
      </joint>
      <link name='lhm_wheel_right_link'>
        <pose frame=''>-0.060298 0.2125 0.306074 0 0.34827 0</pose>
        <inertial>
          <pose frame=''>0 0 0 0 -0 0</pose>
          <mass>0.2</mass>
          <inertia>
            <ixx>0.000532739</ixx>
            <ixy>0</ixy>
            <ixz>0</ixz>
            <iyy>0.000532739</iyy>
            <iyz>0</iyz>
            <izz>0.00104397</izz>
          </inertia>
        </inertial>
        <collision name='lhm_wheel_right_link_collision'>
          <pose frame=''>0 0 0 0 -0 0</pose>
          <geometry>
            <mesh>
              <scale>1 1 1</scale>
              <uri>/home/moyin/dev/autonomous_controllers/src/gazebo_sim/robbie_description/meshes/butt_wheelFini_collision.STL</uri>
            </mesh>
          </geometry>
          <surface>
            <contact>
              <ode/>
            </contact>
            <friction>
              <ode/>
              <torsional>
                <ode/>
              </torsional>
            </friction>
            <bounce/>
          </surface>
          <max_contacts>10</max_contacts>
        </collision>
        <visual name='lhm_wheel_right_link_visual'>
          <pose frame=''>0 0 0 0 -0 0</pose>
          <geometry>
            <mesh>
              <scale>1 1 1</scale>
              <uri>/home/moyin/dev/autonomous_controllers/src/gazebo_sim/robbie_description/meshes/butt_wheelFini.STL</uri>
            </mesh>
          </geometry>
          <material>
            <script>
              <name>Gazebo/Black</name>
              <uri>file://media/materials/scripts/gazebo.material</uri>
            </script>
          </material>
        </visual>
        <gravity>1</gravity>
        <velocity_decay/>
        <self_collide>0</self_collide>
        <kinematic>0</kinematic>
      </link>
      <joint name='lhm_wheel_right_joint' type='revolute'>
        <child>lhm_wheel_right_link</child>
        <parent>lhm_link</parent>
        <axis>
          <xyz>0 1 0</xyz>
          <limit>
            <lower>-1e+16</lower>
            <upper>1e+16</upper>
          </limit>
          <dynamics>
            <spring_reference>0</spring_reference>
            <spring_stiffness>0</spring_stiffness>
          </dynamics>
          <use_parent_model_frame>1</use_parent_model_frame>
        </axis>
      </joint>
      <link name='shoulder_left_link'>
        <pose frame=''>0.087346 0.128 0.624824 0 0.34827 0</pose>
        <inertial>
          <pose frame=''>0 0.16 -0.15 0 -0 0</pose>
          <mass>0.25</mass>
          <inertia>
            <ixx>0.00191406</ixx>
            <ixy>0</ixy>
            <ixz>0</ixz>
            <iyy>0.00191406</iyy>
            <iyz>0</iyz>
            <izz>7.8125e-05</izz>
          </inertia>
        </inertial>
        <collision name='shoulder_left_link_collision'>
          <pose frame=''>0 0 0 0 -0 0</pose>
          <geometry>
            <mesh>
              <scale>1 1 1</scale>
              <uri>/home/moyin/dev/autonomous_controllers/src/gazebo_sim/robbie_description/meshes/shoulderAss.STL</uri>
            </mesh>
          </geometry>
          <surface>
            <contact>
              <ode/>
            </contact>
            <friction>
              <ode/>
              <torsional>
                <ode/>
              </torsional>
            </friction>
            <bounce/>
          </surface>
          <max_contacts>10</max_contacts>
        </collision>
        <visual name='shoulder_left_link_visual'>
          <pose frame=''>0 0 0 0 -0 0</pose>
          <geometry>
            <mesh>
              <scale>1 1 1</scale>
              <uri>/home/moyin/dev/autonomous_controllers/src/gazebo_sim/robbie_description/meshes/shoulderAss.STL</uri>
            </mesh>
          </geometry>
          <material>
            <script>
              <name>Gazebo/Red</name>
              <uri>file://media/materials/scripts/gazebo.material</uri>
            </script>
          </material>
        </visual>
        <gravity>1</gravity>
        <velocity_decay/>
        <self_collide>0</self_collide>
        <kinematic>0</kinematic>
      </link>
      <joint name='shoulder_left_joint' type='revolute'>
        <child>shoulder_left_link</child>
        <parent>torso_link</parent>
        <axis>
          <xyz>0 1 0</xyz>
          <limit>
            <lower>-1e+16</lower>
            <upper>1e+16</upper>
          </limit>
          <dynamics>
            <damping>1</damping>
            <friction>0</friction>
            <spring_reference>0</spring_reference>
            <spring_stiffness>0</spring_stiffness>
          </dynamics>
          <use_parent_model_frame>1</use_parent_model_frame>
        </axis>
      </joint>
      <link name='arm_left_link'>
        <pose frame=''>0.06687 0.288 0.568426 0 0.34827 0</pose>
        <inertial>
          <pose frame=''>0 0 -0.1325 0 -0 0</pose>
          <mass>0.25</mass>
          <inertia>
            <ixx>0.00148802</ixx>
            <ixy>0</ixy>
            <ixz>0</ixz>
            <iyy>0.00148802</iyy>
            <iyz>0</iyz>
            <izz>5e-05</izz>
          </inertia>
        </inertial>
        <collision name='arm_left_link_collision'>
          <pose frame=''>0 0 0 0 -0 0</pose>
          <geometry>
            <mesh>
              <scale>1 1 1</scale>
              <uri>/home/moyin/dev/autonomous_controllers/src/gazebo_sim/robbie_description/meshes/shoulderAss2_lowerfini.STL</uri>
            </mesh>
          </geometry>
          <surface>
            <contact>
              <ode/>
            </contact>
            <friction>
              <ode/>
              <torsional>
                <ode/>
              </torsional>
            </friction>
            <bounce/>
          </surface>
          <max_contacts>10</max_contacts>
        </collision>
        <visual name='arm_left_link_visual'>
          <pose frame=''>0 0 0 0 -0 0</pose>
          <geometry>
            <mesh>
              <scale>1 1 1</scale>
              <uri>/home/moyin/dev/autonomous_controllers/src/gazebo_sim/robbie_description/meshes/shoulderAss2_lowerfini.STL</uri>
            </mesh>
          </geometry>
          <material>
            <script>
              <name>Gazebo/Black</name>
              <uri>file://media/materials/scripts/gazebo.material</uri>
            </script>
          </material>
        </visual>
        <gravity>1</gravity>
        <velocity_decay/>
        <self_collide>0</self_collide>
        <kinematic>0</kinematic>
      </link>
      <joint name='elbow_left_joint' type='prismatic'>
        <child>arm_left_link</child>
        <parent>shoulder_left_link</parent>
        <axis>
          <xyz>0.341272 0 0.939965</xyz>
          <limit>
            <lower>-0.2</lower>
            <upper>0</upper>
            <effort>300</effort>
            <velocity>0.1</velocity>
          </limit>
          <dynamics>
            <damping>1</damping>
            <friction>1</friction>
            <spring_reference>0</spring_reference>
            <spring_stiffness>0</spring_stiffness>
          </dynamics>
          <use_parent_model_frame>1</use_parent_model_frame>
        </axis>
      </joint>
      <link name='shoulder_right_link'>
        <pose frame=''>0.087346 -0.128 0.624824 0 0.34827 0</pose>
        <inertial>
          <pose frame=''>0 -0.16 -0.15 0 -0 0</pose>
          <mass>0.25</mass>
          <inertia>
            <ixx>0.00191406</ixx>
            <ixy>0</ixy>
            <ixz>0</ixz>
            <iyy>0.00191406</iyy>
            <iyz>0</iyz>
            <izz>7.8125e-05</izz>
          </inertia>
        </inertial>
        <collision name='shoulder_right_link_collision'>
          <pose frame=''>0 0 0 0 -0 -3.14159</pose>
          <geometry>
            <mesh>
              <scale>1 1 1</scale>
              <uri>/home/moyin/dev/autonomous_controllers/src/gazebo_sim/robbie_description/meshes/shoulderAss.STL</uri>
            </mesh>
          </geometry>
          <surface>
            <contact>
              <ode/>
            </contact>
            <friction>
              <ode/>
              <torsional>
                <ode/>
              </torsional>
            </friction>
            <bounce/>
          </surface>
          <max_contacts>10</max_contacts>
        </collision>
        <visual name='shoulder_right_link_visual'>
          <pose frame=''>0 0 0 0 -0 -3.14159</pose>
          <geometry>
            <mesh>
              <scale>1 1 1</scale>
              <uri>/home/moyin/dev/autonomous_controllers/src/gazebo_sim/robbie_description/meshes/shoulderAss.STL</uri>
            </mesh>
          </geometry>
          <material>
            <script>
              <name>Gazebo/Red</name>
              <uri>file://media/materials/scripts/gazebo.material</uri>
            </script>
          </material>
        </visual>
        <gravity>1</gravity>
        <velocity_decay/>
        <self_collide>0</self_collide>
        <kinematic>0</kinematic>
      </link>
      <joint name='shoulder_right_joint' type='revolute'>
        <child>shoulder_right_link</child>
        <parent>torso_link</parent>
        <axis>
          <xyz>0 1 0</xyz>
          <limit>
            <lower>-1e+16</lower>
            <upper>1e+16</upper>
          </limit>
          <dynamics>
            <damping>1</damping>
            <friction>0</friction>
            <spring_reference>0</spring_reference>
            <spring_stiffness>0</spring_stiffness>
          </dynamics>
          <use_parent_model_frame>1</use_parent_model_frame>
        </axis>
      </joint>
      <link name='arm_right_link'>
        <pose frame=''>0.06687 -0.288 0.568426 0 0.34827 0</pose>
        <inertial>
          <pose frame=''>0 0 -0.1325 0 -0 0</pose>
          <mass>0.25</mass>
          <inertia>
            <ixx>0.00148802</ixx>
            <ixy>0</ixy>
            <ixz>0</ixz>
            <iyy>0.00148802</iyy>
            <iyz>0</iyz>
            <izz>5e-05</izz>
          </inertia>
        </inertial>
        <collision name='arm_right_link_collision'>
          <pose frame=''>0 0 0 0 -0 0</pose>
          <geometry>
            <mesh>
              <scale>1 1 1</scale>
              <uri>/home/moyin/dev/autonomous_controllers/src/gazebo_sim/robbie_description/meshes/shoulderAss2_lowerfini.STL</uri>
            </mesh>
          </geometry>
          <surface>
            <contact>
              <ode/>
            </contact>
            <friction>
              <ode/>
              <torsional>
                <ode/>
              </torsional>
            </friction>
            <bounce/>
          </surface>
          <max_contacts>10</max_contacts>
        </collision>
        <visual name='arm_right_link_visual'>
          <pose frame=''>0 0 0 0 -0 0</pose>
          <geometry>
            <mesh>
              <scale>1 1 1</scale>
              <uri>/home/moyin/dev/autonomous_controllers/src/gazebo_sim/robbie_description/meshes/shoulderAss2_lowerfini.STL</uri>
            </mesh>
          </geometry>
          <material>
            <script>
              <name>Gazebo/Black</name>
              <uri>file://media/materials/scripts/gazebo.material</uri>
            </script>
          </material>
        </visual>
        <gravity>1</gravity>
        <velocity_decay/>
        <self_collide>0</self_collide>
        <kinematic>0</kinematic>
      </link>
      <joint name='elbow_right_joint' type='prismatic'>
        <child>arm_right_link</child>
        <parent>shoulder_right_link</parent>
        <axis>
          <xyz>0.341272 0 0.939965</xyz>
          <limit>
            <lower>-0.2</lower>
            <upper>0</upper>
            <effort>300</effort>
            <velocity>0.1</velocity>
          </limit>
          <dynamics>
            <damping>1</damping>
            <friction>1</friction>
            <spring_reference>0</spring_reference>
            <spring_stiffness>0</spring_stiffness>
          </dynamics>
          <use_parent_model_frame>1</use_parent_model_frame>
        </axis>
      </joint>
      <link name='stab_link'>
        <pose frame=''>0.225526 0 0.182085 3.14159 1.22173 3.14159</pose>
        <inertial>
          <pose frame=''>0 0 0.04625 0 -0 0</pose>
          <mass>1</mass>
          <inertia>
            <ixx>0.000769354</ixx>
            <ixy>0</ixy>
            <ixz>0</ixz>
            <iyy>0.00526467</iyy>
            <iyz>0</iyz>
            <izz>0.00592135</izz>
          </inertia>
        </inertial>
        <collision name='stab_link_collision'>
          <pose frame=''>0 0 0 0 -0 0</pose>
          <geometry>
            <mesh>
              <scale>1 1 1</scale>
              <uri>/home/moyin/dev/autonomous_controllers/src/gazebo_sim/robbie_description/meshes/stabiliser_collision.stl</uri>
            </mesh>
          </geometry>
          <surface>
            <contact>
              <ode/>
            </contact>
            <friction>
              <ode/>
              <torsional>
                <ode/>
              </torsional>
            </friction>
            <bounce/>
          </surface>
          <max_contacts>10</max_contacts>
        </collision>
        <visual name='stab_link_visual'>
          <pose frame=''>0 0 0 0 -0 0</pose>
          <geometry>
            <mesh>
              <scale>1 1 1</scale>
              <uri>/home/moyin/dev/autonomous_controllers/src/gazebo_sim/robbie_description/meshes/stabiliser.stl</uri>
            </mesh>
          </geometry>
          <material>
            <script>
              <name>Gazebo/Grey</name>
              <uri>file://media/materials/scripts/gazebo.material</uri>
            </script>
          </material>
        </visual>
        <gravity>1</gravity>
        <velocity_decay/>
        <self_collide>0</self_collide>
        <kinematic>0</kinematic>
      </link>
      <joint name='stab_joint' type='revolute'>
        <child>stab_link</child>
        <parent>shank_footprint</parent>
        <axis>
          <xyz>0 1 0</xyz>
          <limit>
            <lower>0</lower>
            <upper>1.5</upper>
            <effort>300</effort>
            <velocity>0.01</velocity>
          </limit>
          <dynamics>
            <spring_reference>0</spring_reference>
            <spring_stiffness>0</spring_stiffness>
          </dynamics>
          <use_parent_model_frame>1</use_parent_model_frame>
        </axis>
      </joint>
      <link name='stab_wheel'>
        <pose frame=''>0.460449 0 0.09658 3.14159 1.22173 3.14159</pose>
        <inertial>
          <pose frame=''>0 0 0 0 -0 0</pose>
          <mass>0.75</mass>
          <inertia>
            <ixx>0.00123987</ixx>
            <ixy>0</ixy>
            <ixz>0</ixz>
            <iyy>0.00123987</iyy>
            <iyz>0</iyz>
            <izz>0.00217741</izz>
          </inertia>
        </inertial>
        <collision name='stab_wheel_collision'>
          <pose frame=''>0 0 0 0 -0 0</pose>
          <geometry>
            <mesh>
              <scale>1 1 1</scale>
              <uri>/home/moyin/dev/autonomous_controllers/src/gazebo_sim/robbie_description/meshes/stabiliserWheel_collision.stl</uri>
            </mesh>
          </geometry>
          <surface>
            <contact>
              <ode/>
            </contact>
            <friction>
              <ode>
                <mu>0</mu>
                <mu2>0</mu2>
              </ode>
              <torsional>
                <ode/>
              </torsional>
            </friction>
            <bounce/>
          </surface>
          <max_contacts>10</max_contacts>
        </collision>
        <visual name='stab_wheel_visual'>
          <pose frame=''>0 0 0 0 -0 0</pose>
          <geometry>
            <mesh>
              <scale>1 1 1</scale>
              <uri>/home/moyin/dev/autonomous_controllers/src/gazebo_sim/robbie_description/meshes/stabiliserWheel.stl</uri>
            </mesh>
          </geometry>
          <material>
            <script>
              <name>Gazebo/Black</name>
              <uri>file://media/materials/scripts/gazebo.material</uri>
            </script>
          </material>
        </visual>
        <gravity>1</gravity>
        <velocity_decay/>
        <self_collide>0</self_collide>
        <kinematic>0</kinematic>
      </link>
      <joint name='stabWheel_joint' type='revolute'>
        <child>stab_wheel</child>
        <parent>stab_link</parent>
        <axis>
          <xyz>0 1 0</xyz>
          <limit>
            <lower>-1e+16</lower>
            <upper>1e+16</upper>
          </limit>
          <dynamics>
            <spring_reference>0</spring_reference>
            <spring_stiffness>0</spring_stiffness>
          </dynamics>
          <use_parent_model_frame>1</use_parent_model_frame>
        </axis>
      </joint>
      <link name='wheel_left_link'>
        <pose frame=''>0 -0.1175 0.1 0 1.22173 0</pose>
        <inertial>
          <pose frame=''>0 0 0 0 -0 0</pose>
          <mass>0.25</mass>
          <inertia>
            <ixx>0.000679197</ixx>
            <ixy>0</ixy>
            <ixz>0</ixz>
            <iyy>0.000679197</iyy>
            <iyz>0</iyz>
            <izz>0.00127225</izz>
          </inertia>
        </inertial>
        <collision name='wheel_left_link_collision'>
          <pose frame=''>0 0 0 0 -0 0</pose>
          <geometry>
            <mesh>
              <scale>1 1 1</scale>
              <uri>/home/moyin/dev/autonomous_controllers/src/gazebo_sim/robbie_description/meshes/driveWheel_collision.stl</uri>
            </mesh>
          </geometry>
          <surface>
            <contact>
              <ode/>
            </contact>
            <friction>
              <ode/>
              <torsional>
                <ode/>
              </torsional>
            </friction>
            <bounce/>
          </surface>
          <max_contacts>10</max_contacts>
        </collision>
        <visual name='wheel_left_link_visual'>
          <pose frame=''>0 0 0 0 -0 0</pose>
          <geometry>
            <mesh>
              <scale>1 1 1</scale>
              <uri>/home/moyin/dev/autonomous_controllers/src/gazebo_sim/robbie_description/meshes/driveWheel.stl</uri>
            </mesh>
          </geometry>
          <material>
            <script>
              <name>Gazebo/Black</name>
              <uri>file://media/materials/scripts/gazebo.material</uri>
            </script>
          </material>
        </visual>
        <gravity>1</gravity>
        <velocity_decay/>
        <self_collide>0</self_collide>
        <kinematic>0</kinematic>
      </link>
      <joint name='wheel_left_joint' type='revolute'>
        <child>wheel_left_link</child>
        <parent>shank_footprint</parent>
        <axis>
          <xyz>0 1 0</xyz>
          <limit>
            <lower>-1e+16</lower>
            <upper>1e+16</upper>
          </limit>
          <dynamics>
            <spring_reference>0</spring_reference>
            <spring_stiffness>0</spring_stiffness>
          </dynamics>
          <use_parent_model_frame>1</use_parent_model_frame>
        </axis>
      </joint>
      <link name='wheel_right_link'>
        <pose frame=''>0 0.1175 0.1 0 1.22173 0</pose>
        <inertial>
          <pose frame=''>0 0 0 0 -0 0</pose>
          <mass>0.25</mass>
          <inertia>
            <ixx>0.000679197</ixx>
            <ixy>0</ixy>
            <ixz>0</ixz>
            <iyy>0.000679197</iyy>
            <iyz>0</iyz>
            <izz>0.00127225</izz>
          </inertia>
        </inertial>
        <collision name='wheel_right_link_collision'>
          <pose frame=''>0 0 0 0 -0 0</pose>
          <geometry>
            <mesh>
              <scale>1 1 1</scale>
              <uri>/home/moyin/dev/autonomous_controllers/src/gazebo_sim/robbie_description/meshes/driveWheel_collision.stl</uri>
            </mesh>
          </geometry>
          <surface>
            <contact>
              <ode/>
            </contact>
            <friction>
              <ode/>
              <torsional>
                <ode/>
              </torsional>
            </friction>
            <bounce/>
          </surface>
          <max_contacts>10</max_contacts>
        </collision>
        <visual name='wheel_right_link_visual'>
          <pose frame=''>0 0 0 0 -0 0</pose>
          <geometry>
            <mesh>
              <scale>1 1 1</scale>
              <uri>/home/moyin/dev/autonomous_controllers/src/gazebo_sim/robbie_description/meshes/driveWheel.stl</uri>
            </mesh>
          </geometry>
          <material>
            <script>
              <name>Gazebo/Black</name>
              <uri>file://media/materials/scripts/gazebo.material</uri>
            </script>
          </material>
        </visual>
        <gravity>1</gravity>
        <velocity_decay/>
        <self_collide>0</self_collide>
        <kinematic>0</kinematic>
      </link>
      <joint name='wheel_right_joint' type='revolute'>
        <child>wheel_right_link</child>
        <parent>shank_footprint</parent>
        <axis>
          <xyz>0 1 0</xyz>
          <limit>
            <lower>-1e+16</lower>
            <upper>1e+16</upper>
          </limit>
          <dynamics>
            <spring_reference>0</spring_reference>
            <spring_stiffness>0</spring_stiffness>
          </dynamics>
          <use_parent_model_frame>1</use_parent_model_frame>
        </axis>
      </joint>
      <plugin name='gazebo_ros_control' filename='libgazebo_ros_control.so'>
        <robotNamespace>/robbie</robotNamespace>
      </plugin>
      <plugin name="lhm_differential_drive_controller" filename="libgazebo_ros_diff_drive.so">
        <alwaysOn>true</alwaysOn>
        <updateRate>100</updateRate>
        <leftJoint>lhm_wheel_left_joint</leftJoint>
        <rightJoint>lhm_wheel_right_joint</rightJoint>
        <wheelSeparation>0.425</wheelSeparation>
        <wheelDiameter>0.20435</wheelDiameter>
        <torque>20</torque>
<!--         <odometryFrame>odom_lhm</odometryFrame>
        <odometryTopic>odom_lhm</odometryTopic>
 -->        <commandTopic>robbie/cmd_vel_lhm</commandTopic>
        <robotBaseFrame>shank_footprint</robotBaseFrame>
        <robotNamespace>/</robotNamespace>
      </plugin>
      <plugin name='differential_drive_controller' filename='libgazebo_ros_diff_drive.so'>
        <alwaysOn>true</alwaysOn>
        <updateRate>100</updateRate>
        <leftJoint>wheel_left_joint</leftJoint>
        <rightJoint>wheel_right_joint</rightJoint>
        <wheelSeparation>0.23</wheelSeparation>
        <wheelDiameter>0.2</wheelDiameter>
        <torque>20</torque>
        <commandTopic>robbie/cmd_vel</commandTopic>
        <odometryTopic>odom</odometryTopic>
        <odometryFrame>odom</odometryFrame>
        <robotBaseFrame>shank_footprint</robotBaseFrame>
        <robotNamespace>/</robotNamespace>
      </plugin>
      <static>0</static>
      <pose frame=''>0 0 0.2 0 -0 0</pose>
    </model>
  </world>
</sdf>
