<sdf version='1.6'>
  <world name='myworld'>
    <light name='sun' type='directional'>
      <cast_shadows>1</cast_shadows>
      <pose frame=''>0 0 10 0 -0 0</pose>
      <diffuse>0.8 0.8 0.8 1</diffuse>
      <specular>0.1 0.1 0.1 1</specular>
      <attenuation>
        <range>1000</range>
        <constant>0.9</constant>
        <linear>0.01</linear>
        <quadratic>0.001</quadratic>
      </attenuation>
      <direction>-0.5 0.5 -1</direction>
    </light>
    <model name='ground_plane'>
      <static>1</static>
      <link name='link'>
        <collision name='collision'>
          <geometry>
            <plane>
              <normal>0 0 1</normal>
              <size>100 100</size>
            </plane>
          </geometry>
          <surface>
            <friction>
              <ode>
                <mu>100</mu>
                <mu2>50</mu2>
              </ode>
              <torsional>
                <ode/>
              </torsional>
            </friction>
            <contact>
              <ode/>
            </contact>
            <bounce/>
          </surface>
          <max_contacts>10</max_contacts>
        </collision>
        <visual name='visual'>
          <cast_shadows>0</cast_shadows>
          <geometry>
            <plane>
              <normal>0 0 1</normal>
              <size>100 100</size>
            </plane>
          </geometry>
          <material>
            <script>
              <uri>file://media/materials/scripts/gazebo.material</uri>
              <name>Gazebo/Grey</name>
            </script>
          </material>
        </visual>
        <self_collide>0</self_collide>
        <kinematic>0</kinematic>
      </link>
    </model>
    <physics name='default_physics' default='0' type='ode'>
      <ode>
        <solver>
          <type>quick</type>
          <iters>50</iters>
          <sor>1.3</sor>
          <use_dynamic_moi_rescaling>0</use_dynamic_moi_rescaling>
        </solver>
        <constraints>
          <cfm>0</cfm>
          <erp>0.2</erp>
          <contact_max_correcting_vel>100</contact_max_correcting_vel>
          <contact_surface_layer>0.001</contact_surface_layer>
        </constraints>
      </ode>
      <max_step_size>0.001</max_step_size>
      <real_time_factor>1</real_time_factor>
      <real_time_update_rate>1000</real_time_update_rate>
    </physics>
    <gravity>0 0 -9.8</gravity>
    <magnetic_field>6e-06 2.3e-05 -4.2e-05</magnetic_field>
    <atmosphere type='adiabatic'/>
    <scene>
      <ambient>0.4 0.4 0.4 1</ambient>
      <background>0.7 0.7 0.7 1</background>
      <shadows>1</shadows>
    </scene>
    <spherical_coordinates>
      <surface_model>EARTH_WGS84</surface_model>
      <latitude_deg>0</latitude_deg>
      <longitude_deg>0</longitude_deg>
      <elevation>0</elevation>
      <heading_deg>0</heading_deg>
    </spherical_coordinates>
    <model name='robbie'>
      <link name='shank_footprint'>
        <pose frame=''>0 0 0 0 -0 0</pose>
        <inertial>
          <pose frame=''>0.163037 0 0.15934 0 -0 0</pose>
          <mass>7</mass>
          <inertia>
            <ixx>0.0904763</ixx>
            <ixy>0</ixy>
            <ixz>-0.0195421</ixz>
            <iyy>0.0870543</iyy>
            <iyz>0</iyz>
            <izz>0.137055</izz>
          </inertia>
        </inertial>
        <collision name='shank_footprint_fixed_joint_lump__shank_link_collision'>
          <pose frame=''>0 0 0.1 0 1.22173 0</pose>
          <geometry>
            <mesh>
              <scale>1 1 1</scale>
              <uri>/home/moyin/dev/autonomous_controllers/src/gazebo_sim/robbie_description/meshes/shank_collision.stl</uri>
            </mesh>
          </geometry>
          <max_contacts>10</max_contacts>
          <surface>
            <contact>
              <ode/>
            </contact>
            <bounce/>
            <friction>
              <torsional>
                <ode/>
              </torsional>
              <ode/>
            </friction>
          </surface>
        </collision>
        <visual name='shank_footprint_fixed_joint_lump__shank_link_visual'>
          <pose frame=''>0 0 0.1 0 1.22173 0</pose>
          <geometry>
            <mesh>
              <scale>1 1 1</scale>
              <uri>/home/moyin/dev/autonomous_controllers/src/gazebo_sim/robbie_description/meshes/shank.stl</uri>
            </mesh>
          </geometry>
        </visual>
        <self_collide>0</self_collide>
        <kinematic>0</kinematic>
      </link>
      <link name='thigh_link'>
        <pose frame=''>0.326073 0 0.218681 0 -1.22173 0</pose>
        <inertial>
          <pose frame=''>0 0 0.1815 0 -0 0</pose>
          <mass>2</mass>
          <inertia>
            <ixx>0.0465375</ixx>
            <ixy>0</ixy>
            <ixz>0</ixz>
            <iyy>0.0293927</iyy>
            <iyz>0</iyz>
            <izz>0.0267782</izz>
          </inertia>
        </inertial>
        <collision name='thigh_link_collision'>
          <pose frame=''>0 0 0 0 -0 0</pose>
          <geometry>
            <mesh>
              <scale>1 1 1</scale>
              <uri>/home/moyin/dev/autonomous_controllers/src/gazebo_sim/robbie_description/meshes/thigh_collision.stl</uri>
            </mesh>
          </geometry>
          <surface>
            <contact>
              <ode/>
            </contact>
            <friction>
              <ode/>
              <torsional>
                <ode/>
              </torsional>
            </friction>
            <bounce/>
          </surface>
          <max_contacts>10</max_contacts>
        </collision>
        <visual name='thigh_link_visual'>
          <pose frame=''>0 0 0 0 -0 0</pose>
          <geometry>
            <mesh>
              <scale>1 1 1</scale>
              <uri>/home/moyin/dev/autonomous_controllers/src/gazebo_sim/robbie_description/meshes/thigh.stl</uri>
            </mesh>
          </geometry>
          <material>
            <script>
              <name>Gazebo/Black</name>
              <uri>file://media/materials/scripts/gazebo.material</uri>
            </script>
          </material>
        </visual>
        <gravity>1</gravity>
        <velocity_decay/>
        <self_collide>0</self_collide>
        <kinematic>0</kinematic>
      </link>
      <joint name='knee_joint' type='revolute'>
        <child>thigh_link</child>
        <parent>shank_footprint</parent>
        <axis>
          <xyz>0 1 0</xyz>
          <limit>
            <lower>0</lower>
            <upper>1</upper>
            <effort>300</effort>
            <velocity>0.1</velocity>
          </limit>
          <dynamics>
            <damping>1</damping>
            <friction>0</friction>
            <spring_reference>0</spring_reference>
            <spring_stiffness>0</spring_stiffness>
          </dynamics>
          <use_parent_model_frame>1</use_parent_model_frame>
        </axis>
      </joint>
      <link name='torso_link'>
        <pose frame=''>-0.015035 0 0.342834 0 0.34827 0</pose>
        <inertial>
          <pose frame=''>0 0 0.192 0 -0 0</pose>
          <mass>16</mass>
          <inertia>
            <ixx>0.36941</ixx>
            <ixy>0</ixy>
            <ixz>0</ixz>
            <iyy>0.240302</iyy>
            <iyz>0</iyz>
            <izz>0.264109</izz>
          </inertia>
        </inertial>
        <collision name='torso_link_collision'>
          <pose frame=''>-0.03 0 -0.042 0 -0 0</pose>
          <geometry>
            <mesh>
              <scale>1 1 1</scale>
              <uri>/home/moyin/dev/autonomous_controllers/src/gazebo_sim/robbie_description/meshes/torso.stl</uri>
            </mesh>
          </geometry>
          <surface>
            <contact>
              <ode/>
            </contact>
            <friction>
              <ode/>
              <torsional>
                <ode/>
              </torsional>
            </friction>
            <bounce/>
          </surface>
          <max_contacts>10</max_contacts>
        </collision>
        <collision name='torso_link_fixed_joint_lump__camera_link_collision_1'>
          <pose frame=''>0 0 0.42 0 -0 0</pose>
          <geometry>
            <box>
              <size>0.05 0.05 0.05</size>
            </box>
          </geometry>
          <surface>
            <contact>
              <ode/>
            </contact>
            <friction>
              <ode/>
              <torsional>
                <ode/>
              </torsional>
            </friction>
            <bounce/>
          </surface>
          <max_contacts>10</max_contacts>
        </collision>
        <visual name='torso_link_visual'>
          <pose frame=''>-0.03 0 -0.042 0 -0 0</pose>
          <geometry>
            <mesh>
              <scale>1 1 1</scale>
              <uri>/home/moyin/dev/autonomous_controllers/src/gazebo_sim/robbie_description/meshes/torso.stl</uri>
            </mesh>
          </geometry>
          <material>
            <script>
              <name>Gazebo/White</name>
              <uri>file://media/materials/scripts/gazebo.material</uri>
            </script>
          </material>
        </visual>
        <visual name='torso_link_fixed_joint_lump__camera_link_visual_1'>
          <pose frame=''>0 0 0.42 0 -0 0</pose>
          <geometry>
            <box>
              <size>0.05 0.05 0.05</size>
            </box>
          </geometry>
          <material>
            <script>
              <uri>__default__</uri>
              <name>__default__</name>
            </script>
          </material>
        </visual>
        <velocity_decay/>
        <gravity>1</gravity>
        <velocity_decay/>
        <sensor name='camera1' type='camera'>
          <update_rate>30</update_rate>
          <camera name='head'>
            <horizontal_fov>1.39626</horizontal_fov>
            <image>
              <width>800</width>
              <height>800</height>
              <format>R8G8B8</format>
            </image>
            <clip>
              <near>0.02</near>
              <far>300</far>
            </clip>
            <noise>
              <type>gaussian</type>
              <mean>0</mean>
              <stddev>0.007</stddev>
            </noise>
          </camera>
          <plugin name='camera_controller' filename='libgazebo_ros_camera.so'>
            <alwaysOn>true</alwaysOn>
            <updateRate>0.0</updateRate>
            <cameraName>robbie/camera1</cameraName>
            <imageTopicName>image_raw</imageTopicName>
            <cameraInfoTopicName>camera_info</cameraInfoTopicName>
            <frameName>camera_link</frameName>
            <hackBaseline>0.07</hackBaseline>
            <distortionK1>0.0</distortionK1>
            <distortionK2>0.0</distortionK2>
            <distortionK3>0.0</distortionK3>
            <distortionT1>0.0</distortionT1>
            <distortionT2>0.0</distortionT2>
            <robotNamespace>/</robotNamespace>
          </plugin>
          <pose frame=''>0 0 0.42 0 -0 0</pose>
        </sensor>
        <self_collide>0</self_collide>
        <kinematic>0</kinematic>
      </link>
      <joint name='hip_joint' type='revolute'>
        <child>torso_link</child>
        <parent>thigh_link</parent>
        <axis>
          <xyz>0 1 0</xyz>
          <limit>
            <lower>-1</lower>
            <upper>0.7</upper>
            <effort>300</effort>
            <velocity>0.1</velocity>
          </limit>
          <dynamics>
            <damping>1</damping>
            <friction>0</friction>
            <spring_reference>0</spring_reference>
            <spring_stiffness>0</spring_stiffness>
          </dynamics>
          <use_parent_model_frame>1</use_parent_model_frame>
        </axis>
      </joint>
      <link name='lhm_link'>
        <pose frame=''>-0.060298 0 0.306074 0 0.34827 0</pose>
        <inertial>
          <pose frame=''>0 0 0.02 0 -0 0</pose>
          <mass>2.25</mass>
          <inertia>
            <ixx>0.021468</ixx>
            <ixy>0</ixy>
            <ixz>0</ixz>
            <iyy>0.0213977</iyy>
            <iyz>0</iyz>
            <izz>0.000529687</izz>
          </inertia>
        </inertial>
        <collision name='lhm_link_collision'>
          <pose frame=''>0 0 0 0 -0 0</pose>
          <geometry>
            <mesh>
              <scale>1 1 1</scale>
              <uri>/home/moyin/dev/autonomous_controllers/src/gazebo_sim/robbie_description/meshes/butt_PART_collision.STL</uri>
            </mesh>
          </geometry>
          <max_contacts>10</max_contacts>
          <surface>
            <contact>
              <ode/>
            </contact>
            <bounce/>
            <friction>
              <torsional>
                <ode/>
              </torsional>
              <ode/>
            </friction>
          </surface>
        </collision>
        <visual name='lhm_link_visual'>
          <pose frame=''>0 0 0 0 -0 0</pose>
          <geometry>
            <mesh>
              <scale>1 1 1</scale>
              <uri>/home/moyin/dev/autonomous_controllers/src/gazebo_sim/robbie_description/meshes/butt_PART.STL</uri>
            </mesh>
          </geometry>
        </visual>
        <self_collide>0</self_collide>
        <kinematic>0</kinematic>
      </link>
      <joint name='lhm_torso_joint' type='prismatic'>
        <child>lhm_link</child>
        <parent>torso_link</parent>
        <axis>
          <xyz>0.341272 0 0.939965</xyz>
          <limit>
            <lower>-0.2</lower>
            <upper>0</upper>
            <effort>300</effort>
            <velocity>0.1</velocity>
          </limit>
          <dynamics>
            <damping>1</damping>
            <friction>0</friction>
            <spring_reference>0</spring_reference>
            <spring_stiffness>0</spring_stiffness>
          </dynamics>
          <use_parent_model_frame>1</use_parent_model_frame>
        </axis>
      </joint>
      <link name='lhm_wheel_left_link'>
        <pose frame=''>-0.060298 -0.2125 0.306074 0 0.34827 0</pose>
        <inertial>
          <pose frame=''>0 0 0 0 -0 0</pose>
          <mass>0.2</mass>
          <inertia>
            <ixx>0.000532739</ixx>
            <ixy>0</ixy>
            <ixz>0</ixz>
            <iyy>0.000532739</iyy>
            <iyz>0</iyz>
            <izz>0.00104397</izz>
          </inertia>
        </inertial>
        <collision name='lhm_wheel_left_link_collision'>
          <pose frame=''>0 0 0 0 -0 0</pose>
          <geometry>
            <mesh>
              <scale>1 1 1</scale>
              <uri>/home/moyin/dev/autonomous_controllers/src/gazebo_sim/robbie_description/meshes/butt_wheelFini_collision.STL</uri>
            </mesh>
          </geometry>
          <surface>
            <contact>
              <ode/>
            </contact>
            <friction>
              <ode/>
              <torsional>
                <ode/>
              </torsional>
            </friction>
            <bounce/>
          </surface>
          <max_contacts>10</max_contacts>
        </collision>
        <visual name='lhm_wheel_left_link_visual'>
          <pose frame=''>0 0 0 0 -0 0</pose>
          <geometry>
            <mesh>
              <scale>1 1 1</scale>
              <uri>/home/moyin/dev/autonomous_controllers/src/gazebo_sim/robbie_description/meshes/butt_wheelFini.STL</uri>
            </mesh>
          </geometry>
          <material>
            <script>
              <name>Gazebo/Black</name>
              <uri>file://media/materials/scripts/gazebo.material</uri>
            </script>
          </material>
        </visual>
        <gravity>1</gravity>
        <velocity_decay/>
        <self_collide>0</self_collide>
        <kinematic>0</kinematic>
      </link>
      <joint name='lhm_wheel_left_joint' type='revolute'>
        <child>lhm_wheel_left_link</child>
        <parent>lhm_link</parent>
        <axis>
          <xyz>0 1 0</xyz>
          <limit>
            <lower>-1e+16</lower>
            <upper>1e+16</upper>
          </limit>
          <dynamics>
            <spring_reference>0</spring_reference>
            <spring_stiffness>0</spring_stiffness>
          </dynamics>
          <use_parent_model_frame>1</use_parent_model_frame>
        </axis>
      </joint>
      <link name='lhm_wheel_right_link'>
        <pose frame=''>-0.060298 0.2125 0.306074 0 0.34827 0</pose>
        <inertial>
          <pose frame=''>0 0 0 0 -0 0</pose>
          <mass>0.2</mass>
          <inertia>
            <ixx>0.000532739</ixx>
            <ixy>0</ixy>
            <ixz>0</ixz>
            <iyy>0.000532739</iyy>
            <iyz>0</iyz>
            <izz>0.00104397</izz>
          </inertia>
        </inertial>
        <collision name='lhm_wheel_right_link_collision'>
          <pose frame=''>0 0 0 0 -0 0</pose>
          <geometry>
            <mesh>
              <scale>1 1 1</scale>
              <uri>/home/moyin/dev/autonomous_controllers/src/gazebo_sim/robbie_description/meshes/butt_wheelFini_collision.STL</uri>
            </mesh>
          </geometry>
          <surface>
            <contact>
              <ode/>
            </contact>
            <friction>
              <ode/>
              <torsional>
                <ode/>
              </torsional>
            </friction>
            <bounce/>
          </surface>
          <max_contacts>10</max_contacts>
        </collision>
        <visual name='lhm_wheel_right_link_visual'>
          <pose frame=''>0 0 0 0 -0 0</pose>
          <geometry>
            <mesh>
              <scale>1 1 1</scale>
              <uri>/home/moyin/dev/autonomous_controllers/src/gazebo_sim/robbie_description/meshes/butt_wheelFini.STL</uri>
            </mesh>
          </geometry>
          <material>
            <script>
              <name>Gazebo/Black</name>
              <uri>file://media/materials/scripts/gazebo.material</uri>
            </script>
          </material>
        </visual>
        <gravity>1</gravity>
        <velocity_decay/>
        <self_collide>0</self_collide>
        <kinematic>0</kinematic>
      </link>
      <joint name='lhm_wheel_right_joint' type='revolute'>
        <child>lhm_wheel_right_link</child>
        <parent>lhm_link</parent>
        <axis>
          <xyz>0 1 0</xyz>
          <limit>
            <lower>-1e+16</lower>
            <upper>1e+16</upper>
          </limit>
          <dynamics>
            <spring_reference>0</spring_reference>
            <spring_stiffness>0</spring_stiffness>
          </dynamics>
          <use_parent_model_frame>1</use_parent_model_frame>
        </axis>
      </joint>
      <link name='shoulder_left_link'>
        <pose frame=''>0.087346 0.128 0.624824 0 0.34827 0</pose>
        <inertial>
          <pose frame=''>0 0.16 -0.15 0 -0 0</pose>
          <mass>0.25</mass>
          <inertia>
            <ixx>0.00191406</ixx>
            <ixy>0</ixy>
            <ixz>0</ixz>
            <iyy>0.00191406</iyy>
            <iyz>0</iyz>
            <izz>7.8125e-05</izz>
          </inertia>
        </inertial>
        <collision name='shoulder_left_link_collision'>
          <pose frame=''>0 0 0 0 -0 0</pose>
          <geometry>
            <mesh>
              <scale>1 1 1</scale>
              <uri>/home/moyin/dev/autonomous_controllers/src/gazebo_sim/robbie_description/meshes/shoulderAss.STL</uri>
            </mesh>
          </geometry>
          <surface>
            <contact>
              <ode/>
            </contact>
            <friction>
              <ode/>
              <torsional>
                <ode/>
              </torsional>
            </friction>
            <bounce/>
          </surface>
          <max_contacts>10</max_contacts>
        </collision>
        <visual name='shoulder_left_link_visual'>
          <pose frame=''>0 0 0 0 -0 0</pose>
          <geometry>
            <mesh>
              <scale>1 1 1</scale>
              <uri>/home/moyin/dev/autonomous_controllers/src/gazebo_sim/robbie_description/meshes/shoulderAss.STL</uri>
            </mesh>
          </geometry>
          <material>
            <script>
              <name>Gazebo/Red</name>
              <uri>file://media/materials/scripts/gazebo.material</uri>
            </script>
          </material>
        </visual>
        <gravity>1</gravity>
        <velocity_decay/>
        <self_collide>0</self_collide>
        <kinematic>0</kinematic>
      </link>
      <joint name='shoulder_left_joint' type='revolute'>
        <child>shoulder_left_link</child>
        <parent>torso_link</parent>
        <axis>
          <xyz>0 1 0</xyz>
          <limit>
            <lower>-1e+16</lower>
            <upper>1e+16</upper>
          </limit>
          <dynamics>
            <damping>1</damping>
            <friction>0</friction>
            <spring_reference>0</spring_reference>
            <spring_stiffness>0</spring_stiffness>
          </dynamics>
          <use_parent_model_frame>1</use_parent_model_frame>
        </axis>
      </joint>
      <link name='arm_left_link'>
        <pose frame=''>0.06687 0.288 0.568426 0 0.34827 0</pose>
        <inertial>
          <pose frame=''>0 0 -0.1325 0 -0 0</pose>
          <mass>0.25</mass>
          <inertia>
            <ixx>0.00148802</ixx>
            <ixy>0</ixy>
            <ixz>0</ixz>
            <iyy>0.00148802</iyy>
            <iyz>0</iyz>
            <izz>5e-05</izz>
          </inertia>
        </inertial>
        <collision name='arm_left_link_collision'>
          <pose frame=''>0 0 0 0 -0 0</pose>
          <geometry>
            <mesh>
              <scale>1 1 1</scale>
              <uri>/home/moyin/dev/autonomous_controllers/src/gazebo_sim/robbie_description/meshes/shoulderAss2_lowerfini.STL</uri>
            </mesh>
          </geometry>
          <surface>
            <contact>
              <ode/>
            </contact>
            <friction>
              <ode/>
              <torsional>
                <ode/>
              </torsional>
            </friction>
            <bounce/>
          </surface>
          <max_contacts>10</max_contacts>
        </collision>
        <visual name='arm_left_link_visual'>
          <pose frame=''>0 0 0 0 -0 0</pose>
          <geometry>
            <mesh>
              <scale>1 1 1</scale>
              <uri>/home/moyin/dev/autonomous_controllers/src/gazebo_sim/robbie_description/meshes/shoulderAss2_lowerfini.STL</uri>
            </mesh>
          </geometry>
          <material>
            <script>
              <name>Gazebo/Black</name>
              <uri>file://media/materials/scripts/gazebo.material</uri>
            </script>
          </material>
        </visual>
        <gravity>1</gravity>
        <velocity_decay/>
        <self_collide>0</self_collide>
        <kinematic>0</kinematic>
      </link>
      <joint name='elbow_left_joint' type='prismatic'>
        <child>arm_left_link</child>
        <parent>shoulder_left_link</parent>
        <axis>
          <xyz>0.341272 0 0.939965</xyz>
          <limit>
            <lower>-0.2</lower>
            <upper>0</upper>
            <effort>300</effort>
            <velocity>0.1</velocity>
          </limit>
          <dynamics>
            <damping>1</damping>
            <friction>1</friction>
            <spring_reference>0</spring_reference>
            <spring_stiffness>0</spring_stiffness>
          </dynamics>
          <use_parent_model_frame>1</use_parent_model_frame>
        </axis>
      </joint>
      <link name='shoulder_right_link'>
        <pose frame=''>0.087346 -0.128 0.624824 0 0.34827 0</pose>
        <inertial>
          <pose frame=''>0 -0.16 -0.15 0 -0 0</pose>
          <mass>0.25</mass>
          <inertia>
            <ixx>0.00191406</ixx>
            <ixy>0</ixy>
            <ixz>0</ixz>
            <iyy>0.00191406</iyy>
            <iyz>0</iyz>
            <izz>7.8125e-05</izz>
          </inertia>
        </inertial>
        <collision name='shoulder_right_link_collision'>
          <pose frame=''>0 0 0 0 -0 -3.14159</pose>
          <geometry>
            <mesh>
              <scale>1 1 1</scale>
              <uri>/home/moyin/dev/autonomous_controllers/src/gazebo_sim/robbie_description/meshes/shoulderAss.STL</uri>
            </mesh>
          </geometry>
          <surface>
            <contact>
              <ode/>
            </contact>
            <friction>
              <ode/>
              <torsional>
                <ode/>
              </torsional>
            </friction>
            <bounce/>
          </surface>
          <max_contacts>10</max_contacts>
        </collision>
        <visual name='shoulder_right_link_visual'>
          <pose frame=''>0 0 0 0 -0 -3.14159</pose>
          <geometry>
            <mesh>
              <scale>1 1 1</scale>
              <uri>/home/moyin/dev/autonomous_controllers/src/gazebo_sim/robbie_description/meshes/shoulderAss.STL</uri>
            </mesh>
          </geometry>
          <material>
            <script>
              <name>Gazebo/Red</name>
              <uri>file://media/materials/scripts/gazebo.material</uri>
            </script>
          </material>
        </visual>
        <gravity>1</gravity>
        <velocity_decay/>
        <self_collide>0</self_collide>
        <kinematic>0</kinematic>
      </link>
      <joint name='shoulder_right_joint' type='revolute'>
        <child>shoulder_right_link</child>
        <parent>torso_link</parent>
        <axis>
          <xyz>0 1 0</xyz>
          <limit>
            <lower>-1e+16</lower>
            <upper>1e+16</upper>
          </limit>
          <dynamics>
            <damping>1</damping>
            <friction>0</friction>
            <spring_reference>0</spring_reference>
            <spring_stiffness>0</spring_stiffness>
          </dynamics>
          <use_parent_model_frame>1</use_parent_model_frame>
        </axis>
      </joint>
      <link name='arm_right_link'>
        <pose frame=''>0.06687 -0.288 0.568426 0 0.34827 0</pose>
        <inertial>
          <pose frame=''>0 0 -0.1325 0 -0 0</pose>
          <mass>0.25</mass>
          <inertia>
            <ixx>0.00148802</ixx>
            <ixy>0</ixy>
            <ixz>0</ixz>
            <iyy>0.00148802</iyy>
            <iyz>0</iyz>
            <izz>5e-05</izz>
          </inertia>
        </inertial>
        <collision name='arm_right_link_collision'>
          <pose frame=''>0 0 0 0 -0 0</pose>
          <geometry>
            <mesh>
              <scale>1 1 1</scale>
              <uri>/home/moyin/dev/autonomous_controllers/src/gazebo_sim/robbie_description/meshes/shoulderAss2_lowerfini.STL</uri>
            </mesh>
          </geometry>
          <surface>
            <contact>
              <ode/>
            </contact>
            <friction>
              <ode/>
              <torsional>
                <ode/>
              </torsional>
            </friction>
            <bounce/>
          </surface>
          <max_contacts>10</max_contacts>
        </collision>
        <visual name='arm_right_link_visual'>
          <pose frame=''>0 0 0 0 -0 0</pose>
          <geometry>
            <mesh>
              <scale>1 1 1</scale>
              <uri>/home/moyin/dev/autonomous_controllers/src/gazebo_sim/robbie_description/meshes/shoulderAss2_lowerfini.STL</uri>
            </mesh>
          </geometry>
          <material>
            <script>
              <name>Gazebo/Black</name>
              <uri>file://media/materials/scripts/gazebo.material</uri>
            </script>
          </material>
        </visual>
        <gravity>1</gravity>
        <velocity_decay/>
        <self_collide>0</self_collide>
        <kinematic>0</kinematic>
      </link>
      <joint name='elbow_right_joint' type='prismatic'>
        <child>arm_right_link</child>
        <parent>shoulder_right_link</parent>
        <axis>
          <xyz>0.341272 0 0.939965</xyz>
          <limit>
            <lower>-0.2</lower>
            <upper>0</upper>
            <effort>300</effort>
            <velocity>0.1</velocity>
          </limit>
          <dynamics>
            <damping>1</damping>
            <friction>1</friction>
            <spring_reference>0</spring_reference>
            <spring_stiffness>0</spring_stiffness>
          </dynamics>
          <use_parent_model_frame>1</use_parent_model_frame>
        </axis>
      </joint>
      <link name='stab_link'>
        <pose frame=''>0.225526 0 0.182085 3.14159 1.22173 3.14159</pose>
        <inertial>
          <pose frame=''>0 0 0.04625 0 -0 0</pose>
          <mass>1</mass>
          <inertia>
            <ixx>0.000769354</ixx>
            <ixy>0</ixy>
            <ixz>0</ixz>
            <iyy>0.00526467</iyy>
            <iyz>0</iyz>
            <izz>0.00592135</izz>
          </inertia>
        </inertial>
        <collision name='stab_link_collision'>
          <pose frame=''>0 0 0 0 -0 0</pose>
          <geometry>
            <mesh>
              <scale>1 1 1</scale>
              <uri>/home/moyin/dev/autonomous_controllers/src/gazebo_sim/robbie_description/meshes/stabiliser_collision.stl</uri>
            </mesh>
          </geometry>
          <surface>
            <contact>
              <ode/>
            </contact>
            <friction>
              <ode/>
              <torsional>
                <ode/>
              </torsional>
            </friction>
            <bounce/>
          </surface>
          <max_contacts>10</max_contacts>
        </collision>
        <visual name='stab_link_visual'>
          <pose frame=''>0 0 0 0 -0 0</pose>
          <geometry>
            <mesh>
              <scale>1 1 1</scale>
              <uri>/home/moyin/dev/autonomous_controllers/src/gazebo_sim/robbie_description/meshes/stabiliser.stl</uri>
            </mesh>
          </geometry>
          <material>
            <script>
              <name>Gazebo/Grey</name>
              <uri>file://media/materials/scripts/gazebo.material</uri>
            </script>
          </material>
        </visual>
        <gravity>1</gravity>
        <velocity_decay/>
        <self_collide>0</self_collide>
        <kinematic>0</kinematic>
      </link>
      <joint name='stab_joint' type='revolute'>
        <child>stab_link</child>
        <parent>shank_footprint</parent>
        <axis>
          <xyz>0 1 0</xyz>
          <limit>
            <lower>0</lower>
            <upper>1.5</upper>
            <effort>300</effort>
            <velocity>0.01</velocity>
          </limit>
          <dynamics>
            <spring_reference>0</spring_reference>
            <spring_stiffness>0</spring_stiffness>
          </dynamics>
          <use_parent_model_frame>1</use_parent_model_frame>
        </axis>
      </joint>
      <link name='stab_wheel'>
        <pose frame=''>0.460449 0 0.09658 3.14159 1.22173 3.14159</pose>
        <inertial>
          <pose frame=''>0 0 0 0 -0 0</pose>
          <mass>0.75</mass>
          <inertia>
            <ixx>0.00123987</ixx>
            <ixy>0</ixy>
            <ixz>0</ixz>
            <iyy>0.00123987</iyy>
            <iyz>0</iyz>
            <izz>0.00217741</izz>
          </inertia>
        </inertial>
        <collision name='stab_wheel_collision'>
          <pose frame=''>0 0 0 0 -0 0</pose>
          <geometry>
            <mesh>
              <scale>1 1 1</scale>
              <uri>/home/moyin/dev/autonomous_controllers/src/gazebo_sim/robbie_description/meshes/stabiliserWheel_collision.stl</uri>
            </mesh>
          </geometry>
          <surface>
            <contact>
              <ode/>
            </contact>
            <friction>
              <ode>
                <mu>0</mu>
                <mu2>0</mu2>
              </ode>
              <torsional>
                <ode/>
              </torsional>
            </friction>
            <bounce/>
          </surface>
          <max_contacts>10</max_contacts>
        </collision>
        <visual name='stab_wheel_visual'>
          <pose frame=''>0 0 0 0 -0 0</pose>
          <geometry>
            <mesh>
              <scale>1 1 1</scale>
              <uri>/home/moyin/dev/autonomous_controllers/src/gazebo_sim/robbie_description/meshes/stabiliserWheel.stl</uri>
            </mesh>
          </geometry>
          <material>
            <script>
              <name>Gazebo/Black</name>
              <uri>file://media/materials/scripts/gazebo.material</uri>
            </script>
          </material>
        </visual>
        <gravity>1</gravity>
        <velocity_decay/>
        <self_collide>0</self_collide>
        <kinematic>0</kinematic>
      </link>
      <joint name='stabWheel_joint' type='revolute'>
        <child>stab_wheel</child>
        <parent>stab_link</parent>
        <axis>
          <xyz>0 1 0</xyz>
          <limit>
            <lower>-1e+16</lower>
            <upper>1e+16</upper>
          </limit>
          <dynamics>
            <spring_reference>0</spring_reference>
            <spring_stiffness>0</spring_stiffness>
          </dynamics>
          <use_parent_model_frame>1</use_parent_model_frame>
        </axis>
      </joint>
      <link name='wheel_left_link'>
        <pose frame=''>0 -0.1175 0.1 0 1.22173 0</pose>
        <inertial>
          <pose frame=''>0 0 0 0 -0 0</pose>
          <mass>0.25</mass>
          <inertia>
            <ixx>0.000679197</ixx>
            <ixy>0</ixy>
            <ixz>0</ixz>
            <iyy>0.000679197</iyy>
            <iyz>0</iyz>
            <izz>0.00127225</izz>
          </inertia>
        </inertial>
        <collision name='wheel_left_link_collision'>
          <pose frame=''>0 0 0 0 -0 0</pose>
          <geometry>
            <mesh>
              <scale>1 1 1</scale>
              <uri>/home/moyin/dev/autonomous_controllers/src/gazebo_sim/robbie_description/meshes/driveWheel_collision.stl</uri>
            </mesh>
          </geometry>
          <surface>
            <contact>
              <ode/>
            </contact>
            <friction>
              <ode/>
              <torsional>
                <ode/>
              </torsional>
            </friction>
            <bounce/>
          </surface>
          <max_contacts>10</max_contacts>
        </collision>
        <visual name='wheel_left_link_visual'>
          <pose frame=''>0 0 0 0 -0 0</pose>
          <geometry>
            <mesh>
              <scale>1 1 1</scale>
              <uri>/home/moyin/dev/autonomous_controllers/src/gazebo_sim/robbie_description/meshes/driveWheel.stl</uri>
            </mesh>
          </geometry>
          <material>
            <script>
              <name>Gazebo/Black</name>
              <uri>file://media/materials/scripts/gazebo.material</uri>
            </script>
          </material>
        </visual>
        <gravity>1</gravity>
        <velocity_decay/>
        <self_collide>0</self_collide>
        <kinematic>0</kinematic>
      </link>
      <joint name='wheel_left_joint' type='revolute'>
        <child>wheel_left_link</child>
        <parent>shank_footprint</parent>
        <axis>
          <xyz>0 1 0</xyz>
          <limit>
            <lower>-1e+16</lower>
            <upper>1e+16</upper>
          </limit>
          <dynamics>
            <spring_reference>0</spring_reference>
            <spring_stiffness>0</spring_stiffness>
          </dynamics>
          <use_parent_model_frame>1</use_parent_model_frame>
        </axis>
      </joint>
      <link name='wheel_right_link'>
        <pose frame=''>0 0.1175 0.1 0 1.22173 0</pose>
        <inertial>
          <pose frame=''>0 0 0 0 -0 0</pose>
          <mass>0.25</mass>
          <inertia>
            <ixx>0.000679197</ixx>
            <ixy>0</ixy>
            <ixz>0</ixz>
            <iyy>0.000679197</iyy>
            <iyz>0</iyz>
            <izz>0.00127225</izz>
          </inertia>
        </inertial>
        <collision name='wheel_right_link_collision'>
          <pose frame=''>0 0 0 0 -0 0</pose>
          <geometry>
            <mesh>
              <scale>1 1 1</scale>
              <uri>/home/moyin/dev/autonomous_controllers/src/gazebo_sim/robbie_description/meshes/driveWheel_collision.stl</uri>
            </mesh>
          </geometry>
          <surface>
            <contact>
              <ode/>
            </contact>
            <friction>
              <ode/>
              <torsional>
                <ode/>
              </torsional>
            </friction>
            <bounce/>
          </surface>
          <max_contacts>10</max_contacts>
        </collision>
        <visual name='wheel_right_link_visual'>
          <pose frame=''>0 0 0 0 -0 0</pose>
          <geometry>
            <mesh>
              <scale>1 1 1</scale>
              <uri>/home/moyin/dev/autonomous_controllers/src/gazebo_sim/robbie_description/meshes/driveWheel.stl</uri>
            </mesh>
          </geometry>
          <material>
            <script>
              <name>Gazebo/Black</name>
              <uri>file://media/materials/scripts/gazebo.material</uri>
            </script>
          </material>
        </visual>
        <gravity>1</gravity>
        <velocity_decay/>
        <self_collide>0</self_collide>
        <kinematic>0</kinematic>
      </link>
      <joint name='wheel_right_joint' type='revolute'>
        <child>wheel_right_link</child>
        <parent>shank_footprint</parent>
        <axis>
          <xyz>0 1 0</xyz>
          <limit>
            <lower>-1e+16</lower>
            <upper>1e+16</upper>
          </limit>
          <dynamics>
            <spring_reference>0</spring_reference>
            <spring_stiffness>0</spring_stiffness>
          </dynamics>
          <use_parent_model_frame>1</use_parent_model_frame>
        </axis>
      </joint>
      <plugin name='gazebo_ros_control' filename='libgazebo_ros_control.so'>
        <robotNamespace>/robbie</robotNamespace>
      </plugin>
      <plugin name='differential_drive_controller' filename='libgazebo_ros_diff_drive.so'>
        <alwaysOn>true</alwaysOn>
        <updateRate>100</updateRate>
        <leftJoint>wheel_left_joint</leftJoint>
        <rightJoint>wheel_right_joint</rightJoint>
        <wheelSeparation>0.23</wheelSeparation>
        <wheelDiameter>0.2</wheelDiameter>
        <torque>20</torque>
        <commandTopic>robbie/cmd_vel</commandTopic>
        <odometryTopic>odom</odometryTopic>
        <odometryFrame>odom</odometryFrame>
        <robotBaseFrame>shank_footprint</robotBaseFrame>
        <robotNamespace>/</robotNamespace>
      </plugin>
      <static>0</static>
      <plugin name='lhm_differential_drive_controller' filename='libgazebo_ros_diff_drive.so'>
        <alwaysOn>true</alwaysOn>
        <updateRate>100</updateRate>
        <leftJoint>lhm_wheel_left_joint</leftJoint>
        <rightJoint>lhm_wheel_right_joint</rightJoint>
        <wheelSeparation>0.425</wheelSeparation>
        <wheelDiameter>0.20435</wheelDiameter>
        <torque>20</torque>
        <commandTopic>robbie/cmd_vel_lhm</commandTopic>
        <odometryTopic>lhm_odom</odometryTopic>
        <odometryFrame>lhm_odom</odometryFrame>
        <robotBaseFrame>shank_footprint</robotBaseFrame>
        <robotNamespace>/</robotNamespace>
      </plugin>
      <pose frame=''>0 0 0 0 -0 0</pose>
    </model>
    <model name='step_0.04m'>
      <pose frame=''>1.60903 0.245966 0 0 -0 0</pose>
      <link name='Stairs_1'>
        <visual name='Stairs_1_Visual_0'>
          <pose frame=''>-0 -0 0.02 0 -0 0</pose>
          <geometry>
            <box>
              <size>2 3.5 0.04</size>
            </box>
          </geometry>
          <material>
            <script>
              <uri>file://media/materials/scripts/gazebo.material</uri>
              <name>Gazebo/Grey</name>
            </script>
            <ambient>0.996078 0.47451 0.0196078 1</ambient>
          </material>
          <meta>
            <layer>0</layer>
          </meta>
        </visual>
        <collision name='Stairs_1_Collision_0'>
          <geometry>
            <box>
              <size>2 3.5 0.04</size>
            </box>
          </geometry>
          <pose frame=''>-0 -0 0.02 0 -0 0</pose>
          <max_contacts>10</max_contacts>
          <surface>
            <contact>
              <ode/>
            </contact>
            <bounce/>
            <friction>
              <torsional>
                <ode/>
              </torsional>
              <ode/>
            </friction>
          </surface>
        </collision>
        <self_collide>0</self_collide>
        <kinematic>0</kinematic>
      </link>
      <static>1</static>
    </model>
    <state world_name='myworld'>
      <sim_time>65 779000000</sim_time>
      <real_time>79 514927908</real_time>
      <wall_time>1489520032 522440850</wall_time>
      <iterations>65779</iterations>
      <model name='ground_plane'>
        <pose frame=''>0 0 0 0 -0 0</pose>
        <scale>1 1 1</scale>
        <link name='link'>
          <pose frame=''>0 0 0 0 -0 0</pose>
          <velocity>0 0 0 0 -0 0</velocity>
          <acceleration>0 0 0 0 -0 0</acceleration>
          <wrench>0 0 0 0 -0 0</wrench>
        </link>
      </model>
      <model name='robbie'>
        <pose frame=''>0.074985 0.055448 0.001477 -1.7e-05 0.049768 0.048991</pose>
        <scale>1 1 1</scale>
        <link name='arm_left_link'>
          <pose frame=''>0.260186 0.352877 0.257648 -5.3e-05 0.301739 0.048923</pose>
          <velocity>-0.00093 -0.000326 -0.002816 0.01752 -0.015796 0.023808</velocity>
          <acceleration>0.884093 1.02719 -8.90842 1.12291 -0.315029 2.67605</acceleration>
          <wrench>0.221023 0.256797 -2.2271 0 -0 0</wrench>
        </link>
        <link name='arm_right_link'>
          <pose frame=''>0.269571 -0.223354 0.252749 -1.4e-05 0.369275 0.048999</pose>
          <velocity>0.001635 -0.000246 -0.00543 0.003424 -0.002454 0.003193</velocity>
          <acceleration>0.411687 0.926728 -9.8552 -0.722688 1.22631 0.046272</acceleration>
          <wrench>0.102922 0.231682 -2.4638 0 -0 0</wrench>
        </link>
        <link name='lhm_link'>
          <pose frame=''>-0.158938 0.043985 0.257466 2.5e-05 1.09799 0.049016</pose>
          <velocity>0.001498 -0.004675 -0.008684 0.000646 -0.005704 0.009937</velocity>
          <acceleration>0.737673 -0.205094 -10.92 -2.32089 -0.728157 -2.18799</acceleration>
          <wrench>1.65976 -0.461461 -24.5699 0 -0 0</wrench>
        </link>
        <link name='lhm_wheel_left_link'>
          <pose frame=''>-0.148536 -0.16826 0.257466 2.4e-05 1.09844 0.049014</pose>
          <velocity>0.004388 -0.004527 -0.009157 0.000626 -0.005713 0.009924</velocity>
          <acceleration>1.53 -0.172488 -10.4313 -2.43755 1.02434 3.07898</acceleration>
          <wrench>0.306 -0.034498 -2.08627 0 -0 0</wrench>
        </link>
        <link name='lhm_wheel_right_link'>
          <pose frame=''>-0.169345 0.25623 0.257462 -6.6e-05 1.10017 0.048914</pose>
          <velocity>-0.000123 -0.004751 -0.007794 0.007504 -0.005371 0.013328</velocity>
          <acceleration>0.715378 -0.213452 -10.156 2.39748 1.23686 -1.77403</acceleration>
          <wrench>0.143076 -0.04269 -2.0312 0 -0 0</wrench>
        </link>
        <link name='shank_footprint'>
          <pose frame=''>0.074985 0.055448 0.001477 -1.7e-05 0.049768 0.048991</pose>
          <velocity>-0.005346 -0.001085 0.002019 0.003448 0.034276 0.007179</velocity>
          <acceleration>0.848233 0.428226 -6.80597 1.5083 0.373994 2.84295</acceleration>
          <wrench>5.93763 2.99758 -47.6418 0 -0 0</wrench>
        </link>
        <link name='shoulder_left_link'>
          <pose frame=''>0.337514 0.196481 0.481211 -2.8e-05 0.301735 0.048965</pose>
          <velocity>-0.002168 -0.00118 -0.003191 0.009679 -0.015219 0.013184</velocity>
          <acceleration>-1.56861 0.050549 -4.47845 -1.42464 0.764196 2.43469</acceleration>
          <wrench>-0.392153 0.012637 -1.11961 0 -0 0</wrench>
        </link>
        <link name='shoulder_right_link'>
          <pose frame=''>0.35005 -0.059211 0.481215 -1.8e-05 0.369268 0.048991</pose>
          <velocity>0.000739 -0.001204 -0.004568 0.005318 -0.000732 0.005663</velocity>
          <acceleration>-0.259758 0.188677 -5.06002 -2.07936 0.178315 2.49127</acceleration>
          <wrench>-0.06494 0.047169 -1.265 0 -0 0</wrench>
        </link>
        <link name='stab_link'>
          <pose frame=''>0.309009 0.066926 0.172121 -3.14158 1.17202 -3.09256</pose>
          <velocity>0.000354 -6.9e-05 -0.006938 7e-06 0.051578 0.001121</velocity>
          <acceleration>0.025186 -0.992509 -14.8109 1.18058 -0.736379 1.76769</acceleration>
          <wrench>0.025186 -0.992509 -14.8109 0 -0 0</wrench>
        </link>
        <link name='stab_wheel'>
          <pose frame=''>0.539107 0.078208 0.075047 3.14153 1.47277 -3.09264</pose>
          <velocity>-0.002374 0.001583 -0.018168 0.002703 -0.062785 0.000915</velocity>
          <acceleration>-1.04626 -1.14085 -28.9305 0.746257 -0.271567 -2.27555</acceleration>
          <wrench>-0.784694 -0.855636 -21.6979 0 -0 0</wrench>
        </link>
        <link name='thigh_link'>
          <pose frame=''>0.411129 0.071933 0.203651 -3.9e-05 -1.172 0.049027</pose>
          <velocity>0.001366 0.00063 -0.005862 0.004985 -0.006915 0.007687</velocity>
          <acceleration>1.4191 0.241122 -9.6516 0.882921 -1.53643 -2.78776</acceleration>
          <wrench>2.83821 0.482243 -19.3032 0 -0 0</wrench>
        </link>
        <link name='torso_link'>
          <pose frame=''>0.077017 0.055553 0.344603 -3.5e-05 1.098 0.04896</pose>
          <velocity>0.000184 -0.002586 -0.007383 0.005336 -0.007909 0.007563</velocity>
          <acceleration>-0.233785 -0.334412 -8.19162 -0.820769 -0.978776 1.22714</acceleration>
          <wrench>-3.74056 -5.35059 -131.066 0 -0 0</wrench>
        </link>
        <link name='wheel_left_link'>
          <pose frame=''>0.08571 -0.061666 0.101374 -0.000117 1.26175 0.048873</pose>
          <velocity>-0.001804 -0.001185 -0.003617 0.008264 0.034447 0.008944</velocity>
          <acceleration>-1.68103 -0.767793 -12.0847 3.01216 -0.77308 1.67372</acceleration>
          <wrench>-0.420257 -0.191948 -3.02116 0 -0 0</wrench>
        </link>
        <link name='wheel_right_link'>
          <pose frame=''>0.074206 0.173047 0.101365 -0.000283 1.2631 0.048706</pose>
          <velocity>-0.002471 -0.000818 -0.000734 0.008688 -0.023248 0.000425</velocity>
          <acceleration>0.098108 0.448018 -1.04845 1.40901 0.527567 2.9339</acceleration>
          <wrench>0.024527 0.112004 -0.262112 0 -0 0</wrench>
        </link>
      </model>
      <model name='step_0.04m'>
        <pose frame=''>1.60903 0.245966 0 0 -0 0</pose>
        <scale>1 1 1</scale>
        <link name='Stairs_1'>
          <pose frame=''>1.60903 0.245966 0 0 -0 0</pose>
          <velocity>0 0 0 0 -0 0</velocity>
          <acceleration>0 0 0 0 -0 0</acceleration>
          <wrench>0 0 0 0 -0 0</wrench>
        </link>
      </model>
      <light name='sun'>
        <pose frame=''>0 0 10 0 -0 0</pose>
      </light>
    </state>
    <gui fullscreen='0'>
      <camera name='user_camera'>
        <pose frame=''>0.876465 -6.6779 1.16781 0 0.127643 1.52419</pose>
        <view_controller>orbit</view_controller>
        <projection_type>perspective</projection_type>
      </camera>
    </gui>
  </world>
</sdf>
